Workbook
Name RangoNombre1: HONORARIOS!$B$5:$H$19

Sheet HONORARIOS
A2: Comisión de Seguridad Social - Asociación de Abogados de Buenos Aires
L3: TRUE
L4: FALSE
K5: Excepciones?
B6: Ley 27.423 | K6: FALSE
B7: (procesos o etapas iniciados a partir de 22-Dic-2017)
B8: UMA AL CORTE CORTE | C8: =VLOOKUP($J$11,PARAMETROS!A2:D82,3) -> 66436 | I8: COMPLETAR
B9: UMAs del Monto Base | C9: =+$J$10/$C$8 -> 150.5208 | D9: Grado de la escala art. 21 | G9: =VLOOKUP(C9,PARAMETROS!F2:L8,7) -> 4º | K9: 45443
B10: UMA ACTUAL | C10: =VLOOKUP($J$12,PARAMETROS!A2:D102,3) -> 92482 | I10: RETROACTIVO APROBADO: | J10: 10000000 | K10: 44746
I11: FECHA DE CORTE DE LIQUIDACION | J11: 45657
B12: Conocimiento (art. 21) | I12: FECHA DE REGULACION | J12: 46156
B13: =IF(D13=0,"","Máx límite grado anterior") -> Máx límite grado anterior | C13: =VLOOKUP($C$9,PARAMETROS!$F$2:$J$8,5) -> 0.24 | D13: =+F13*C8 -> 1435017.6 | F13: =VLOOKUP($C$9,PARAMETROS!$F$2:$K$8,6)*C13 -> 21.6 | G13: =IF(D13=0,"","UMAs") -> UMAs | K13: 30/0
B14: =IF(C13=0,"Mínimo","Excedente") -> Excedente | C14: =VLOOKUP($C$9,PARAMETROS!$F$2:$I$8,3) -> 0.17 | D14: =+F14*C8 -> 683529.2 | F14: =(C9-VLOOKUP($C$9,PARAMETROS!$F$2:$K$8,6))*C14 -> 10.288536 | G14: UMAs
B15: TOTAL CON UMA ACTUAL | D15: =F15*C10 -> 2949115.6 | F15: =+F13+F14 -> 31.888536 | G15: UMAs | K15: 6035195.6
I16: RESULTADOS HONORARIOS EJECUCION
B17: Ejecución (art. 41) | J17: UMAS | K17: PESOS
B18: =CONCATENATE("Reducción 50%",(IF(K6=FALSE," + 10% (por ausencia de excepciones)",""))) -> Reducción 50% + 10% (por ausencia de excepciones) | D18: =((D13+D14)/2)*(IF(K6=FALSE,0.9,1)) -> 953346.06 | F18: =D18/$C$8 -> 14.349841 | G18: UMAs | I18: PRIMERA ETAPA: | J18: =CEILING(F18/2, 0.5) -> 7.5 | K18: =J18*C10 -> 693615
C19: CON UMA ACTUAL: | D19: =C10*F18 -> 1327102 | I19: 1RA LIQUIDACION (AMBAS ETAPAS) | J19: =CEILING(F18*0.9, 0.5) -> 13 | K19: =J19*C10 -> 1202266
B20: =F18*0.4 -> 5.7399365 | D20: =+D18*1.4 -> 1334684.5 | F20: =D20/$C$8 -> 20.089778 | G20: UMAs | I20: SEGUNDA ETAPA (40%): | J20: =CEILING(F18*0.4, 0.5) -> 6 | K20: =J20*C10 -> 554892
I21: ACTUALIZADA (Fallo Finn): | J21: =CEILING(F18/2, 0.5) -> 7.5 | K21: =J21*C10 -> 693615
I22: LIQUIDACION DE PERITOS (70%): | J22: =CEILING(F18*0.9*0.7, 0.5) -> 9.5 | K22: =J22*C10 -> 878579
B23: 1

Sheet PARAMETROS
A1: Desde | B1: Hasta | C1: Valor UMA | D1: Acordada | F1: Desde | G1: Hasta | H1: Mínimo | I1: Máximo | J1: Maxímo límite anterior | L1: Grado
A2: 1 | B2: 43100 | C2: 1350 | D2: 27/2018 | F2: 0 | G2: 15 | H2: 0.22 | I2: 0.33 | L2: 1º
A3: 43101 | B3: 43190 | C3: 1417 | D3: 27/2018 | F3: =+G2+1 -> 16 | G3: 45 | H3: 0.2 | I3: 0.26 | J3: =+I2 -> 0.33 | K3: =+G2 -> 15 | L3: 2º
A4: 43191 | B4: 43312 | C4: 1559 | D4: 7499351.3 | F4: =+G3+1 -> 46 | G4: 90 | H4: 0.18 | I4: 0.24 | J4: =+I3 -> 0.26 | K4: =+G3 -> 45 | L4: 3º
A5: 43313 | B5: 43373 | C5: 1715 | D5: 27/2018 | F5: =+G4+1 -> 91 | G5: 150 | H5: 0.17 | I5: 0.22 | J5: =+I4 -> 0.24 | K5: =+G4 -> 90 | L5: 4º
A6: 43374 | B6: 43524 | C6: 1887 | D6: 3/2019 | F6: =+G5+1 -> 151 | G6: 450 | H6: 0.15 | I6: 0.2 | J6: =+I5 -> 0.22 | K6: =+G5 -> 150 | L6: 5º
A7: 43525 | B7: 43585 | C7: 2075 | D7: 8/2019 | F7: =+G6+1 -> 451 | G7: 750 | H7: 0.13 | I7: 0.17 | J7: =+I6 -> 0.2 | K7: =+G6 -> 450 | L7: 6º
A8: 43586 | B8: 43616 | C8: 2231 | D8: 20/2019 | F8: =+G7+1 -> 751 | H8: 0.12 | I8: 0.15 | J8: =+I7 -> 0.17 | K8: =+G7 -> 750 | L8: 7º
A9: 43617 | B9: 43708 | C9: 2398 | D9: 20/2019
A10: 43709 | B10: 43769 | C10: 2638 | D10: 28/2019
A11: 43770 | B11: 43799 | C11: 2902 | D11: 30/2019
A12: 43800 | B12: 44104 | C12: 3192 | D12: 2/2020
A13: 44105 | B13: 44135 | C13: 3511 | D13: 36/2020
A14: 44136 | B14: 44165 | C14: 3862 | D14: 1/2021
A15: 44166 | B15: 43889 | C15: 4152 | D15: 7/2021
A16: 44256 | B16: 44347 | C16: 4567 | D16: 12/2021
A17: 44348 | B17: 44439 | C17: 4978 | D17: 12/2021
A18: 44440 | B18: 44500 | C18: 6160 | D18: 20/2021
A19: 44501 | B19: 44592 | C19: 6468 | D19: 28/2021
A20: 44593 | B20: 44651 | C20: 7439 | D20: 4/2022
... A25: 44896 | B25: 44926 | C25: 12479 | D25: 3//2023
A26: 44927 | B26: 44957 | C26: 13220 | D26: 45170
A27: 44958 | B27: 44985 | C27: 14154 | D27: 45170
A28: 44986 | B28: 45016 | C28: 14933 | D28: 9//2023
A29: 45017 | B29: 45046 | C29: 16277 | D29: 19//2023
A30: 45047 | B30: 45077 | C30: 17741 | D30: 19//2023
A31: 45078 | B31: 45107 | C31: 19338 | D31: 19//2023
A32: 45108 | B32: 45138 | C32: 20595 | D32: 29//2023
A33: 45139 | B33: 45138 | C33: 23067 | D33: 2722/2023
A34: 45170 | B34: 45199 | C34: 25373 | D34: 2722/2023
A35: 45200 | B35: 45229 | C35: 27784 | D35: 3369/2023
A36: 45231 | B36: 45260 | C36: 30562 | D36: 3369/2023
A37: 45261 | B37: 45291 | C37: 34382 | D37: 3370/2024
A38: 45292 | B38: 45322 | C38: 40571 | D38: 04//2024
A39: 45323 | B39: 45351 | C39: 45440 | D39: 626/2024
... A62: 46023 | B62: 46053 | C62: 89875 | D62: 235/2026
A63: 46054 | B63: =TODAY() -> 46156 | C63: 92482 | D63: 538/2026

Sheet UMAS HISTORICAS
A2: UMA: UNIDAD DE MEDIDA ARANCELARIA
A3: ACORDADA/RESOLU | B3: FECHA | C3: MONTO | D3: VIGENCIA
D4: PERÍODO | E4: FECHA
A7: 27/2018 (2) | B7: 43347 | C7: 1417 | D7: 43101 | E7: 43101
A8: 27/2018 (2) | B8: 43347 | C8: 1559 | D8: 43191 | E8: 43191
A9: 27/2018 (2) | B9: 43347 | C9: 1715 | D9: 43313 | E9: 43313
A10: 43525 | B10: 43499 | C10: 1887 | D10: 43374 | E10: 43374
A11: 43678 | B11: 43570 | C11: 2075 | D11: 43525 | E11: 43525
A12: 20/2019 | B12: 43662 | C12: 2231 | D12: 43586 | E12: 43586
A13: 20/2019 | B13: 43662 | C13: 2398 | D13: 43617 | E13: 43617
A14: 28/2019 | B14: 43767 | C14: 2638 | D14: 43709 | E14: 43709
A15: 30/2019 | B15: 43790 | C15: 2902 | D15: 43770 | E15: 43709
A16: 43862 | B16: 43893 | C16: 3192 | D16: 43800 | E16: 43800
A17: 36/2020 | B17: 44165 | C17: 3511 | D17: 44105 | E17: 44105
A18: 44197 | B18: 44250 | C18: 3862 | D18: 44136 | E18: 44136
A19: 44378 | B19: 44306 | C19: 4152 | D19: 44166 | E19: 44166
A20: 44531 | B20: 44390 | C20: 4567 | D20: 44256 | E20: 44256
A21: 44531 | B21: 44390 | C21: 4978 | D21: 44348 | E21: 44348
A22: 21/2021 | B22: 44470 | C22: 5476 | D22: 44378 | E22: 44378
A23: 21/2021 | B23: 44470 | C23: 6160 | D23: 44440 | E23: 44440
A24: 28/2021 | B24: 44539 | C24: 6468 | D24: 44501 | E24: 44501
A25: 44652 | B25: 44631 | C25: 7439 | D25: 44562 | E25: 44562
A26: 44896 | B26: 44704 | C26: 8183 | D26: 44652 | E26: 44652
A27: 44896 | B27: 44704 | C27: 9001 | D27: 44682 | E27: 44682
A28: 25/2022 | B28: 44812 | C28: 9811 | D28: 44743 | E28: 44743
A29: 25/2022 | B29: 44812 | C29: 10400 | D29: 44805 | E29: 44805
A30: 44986 | B30: 44981 | C30: 12479 | D30: 44896 | E30: 44897
A31: 45170 | B31: 45020 | C31: 13220 | D31: 44927 | E31: 44927
A32: 45170 | B32: 45020 | C32: 14154 | D32: 44958 | E32: 44958
A33: 45170 | B33: 45020 | C33: 14933 | D33: 44986 | E33: 44986
A34: 19/2023 | B34: 45091 | C34: 16277 | D34: 45017 | E34: 45017
A35: 19/2023 | B35: 45091 | C35: 17741 | D35: 45047 | E35: 45047
A36: 19/2023 | B36: 45091 | C36: 19338 | D36: 45078 | E36: 45078
A37: 29/2023 | B37: 45191 | C37: 20595 | D37: 45108 | E37: 45108
A38: Res2722/23 | B38: 45211 | C38: 23067 | D38: 45139 | E38: 45139
A39: Res 2722/23 | B39: 45211 | C39: 25373 | D39: 45170 | E39: 45170
A40: Res 3369/23 | B40: 45264 | C40: 27784 | D40: 45200 | E40: 45200
A41: Res 3369/23 | B41: 45264 | C41: 30562 | D41: 45231 | E41: 45231
A42: Res 12/24 | B42: 45323 | C42: 34382 | D42: 45261 | E42: 45261
A43: Res 176/24 | B43: 45343 | C43: 40571 | D43: 45292 | E43: 45292
...
